Workbook
Name D: [1]Sheet1!$A$1:$A$10

Sheet INTERACTION-PAGE
A1: ATTAINMENT CRITERIA | C1: 70 | E1: 3 | G1: PASSING MARKS (%) | N1: 30
C2: 60 | E2: 2 | F2: =C1-C2 -> 10 | G2: Threshold % for CO attainment | N2: 60
C3: 50 | E3: 1 | F3: =C2-C3 -> 10 | G3: Please fill "AB" for Absent and "UR" for Unregistered or withdeawn student(s)
A4: TEZPUR UNIVERSITY
A5: Faculty Name: | C5: Dr S. S. Satapathy | G5: BRANCH | I5: Mechanical Engineering | N5: Course | Z5: Introductory Computing
A6: Programme: | C6: B. Tech | E6: YEAR | G6: I | I6: SEM | K6: II | M6: Course Code | Z6: CO103 | AB6: SESSION | AD6: 2021-22 | AF6: I
E7: Assessment of TEST -I | J7: Assessment of TEST -II | O7: Assessment of Mid Sem Exam | T7: Assessment of End Sem Exam | AF7: II
A8: S. No. | B8: Roll No. | C8: Name of Student | D8: ABSENTEE RECORD | E8: Maximum Marks | I8: =SUM(E10:I10) -> 25 | J8: Maximum Marks | N8: =SUM(J10:N10) -> 25 | O8: Maximum Marks | S8: =SUM(O10:S10) -> 40 | T8: Maximum Marks | X8: =SUM(T10:X10) -> 60 | Y8: TOTAL | Z8: CO1 | AA8: CO2 | AB8: CO3 | AC8: CO4 | AD8: CO5 | AE8: ΣCO | AF8: III
E9: CO1 | F9: CO2 | G9: CO3 | H9: CO4 | I9: CO5 | J9: CO1 | K9: CO2 | L9: CO3 | M9: CO4 | N9: CO5 | O9: CO1 | P9: CO2 | Q9: CO3 | R9: CO4 | S9: CO5 | T9: CO1 | U9: CO2 | V9: CO3 | W9: CO4 | X9: CO5 | Y9: % | Z9: % | AA9: % | AB9: % | AC9: % | AD9: % | AE9: % | AF9: IV
C10: CO WISE MAXIMUM MARKS | D10: "AB" or "UR" | E10: 10 | F10: 15 | G10: 0 | H10: 0 | I10: 0 | J10: 15 | K10: 10 | L10: 0 | M10: 0 | N10: 0 | O10: 6 | P10: 4 | Q10: 20 | R10: 10 | S10: 0 | T10: 5 | U10: 10 | V10: 20 | W10: 25 | X10: 0 | Y10: =100 * SUM(E10:X10) / SUM(I$8, N$8, S$8, X$8) -> 100 | Z10: =IF((E10+J10+O10+T10)>0,100,"") -> 100 | AA10: =IF((F10+K10+P10+U10)>0,100,"") -> 100 | AB10: =IF((G10+L10+Q10+V10)>0,100,"") -> 100 | AC10: =IF((H10+M10+R10+W10)>0,100,"") -> 100 | AD10: =IF((I10+N10+S10+X10)>0,100,"") | AE10: =IFERROR(AVERAGE(Z10:AD10),"") -> 100
A11: 1 | B11: MEB21001 | C11: NEKIBUR RAHMAN | E11: 5 | F11: 7 | J11: 13 | K11: 8 | O11: 3 | P11: 2 | Q11: 8 | R11: 4 | T11: 1 | U11: 3 | V11: 6 | W11: 7 | Y11: =IF(OR( $B17="", $B17="AB", $B17="UR", $C17="", $C17="AB", $C17="UR", $D17="AB", $D17="UR"),"",(IF(OR(I$8>0,N$8>0,S$8>0,X$8>0),(100*SUM(E17:X17)/(I$8+N$8+S$8+X$8))," "))) -> 55.666667
A12: 2 | B12: MEB21003 | C12: NILOATPAL MAZUMDER | E12: 8 | F12: 13 | J12: 14 | K12: 9 | O12: 3 | P12: 2 | Q12: 12 | R12: 6 | T12: 3 | U12: 5 | V12: 11 | W12: 13
A13: 3 | B13: MEB21004 | C13: SHAHIL ALI MOSSADDIQUE | E13: 5 | F13: 6.5 | J13: 14 | K13: 9 | O13: 2 | P13: 2 | Q13: 7 | R13: 4 | T13: 1 | U13: 1 | V13: 2 | W13: 2
A14: 4 | B14: MEB21005 | C14: CHANDRAK BHATTACHARJEE | E14: 8 | F14: 11.5 | J14: 13 | K14: 8 | O14: 4 | P14: 2 | Q14: 12.5 | R14: 6 | T14: 3 | U14: 5 | V14: 10 | W14: 12
A15: 5 | B15: MEB21006 | C15: SIVAM KARMAKAR | E15: 9 | F15: 12.5 | J15: 11 | K15: 8 | O15: 4 | P15: 3 | Q15: 13.5 | R15: 7 | T15: 2 | U15: 4 | V15: 9 | W15: 11
A16: 6 | B16: MEB21007 | C16: CHIRANJEEV SHUBHAM | E16: 6 | F16: 9 | J16: 14 | K16: 9 | O16: 3 | P16: 2 | Q16: 10 | R16: 5 | T16: 2 | U16: 4 | V16: 7 | W16: 9
A17: 7 | B17: MEB21009 | C17: OWEN RUMON GARG | E17: 7 | F17: 11 | J17: 14 | K17: 9 | O17: 3 | P17: 2 | Q17: 10.5 | R17: 5 | T17: 2 | U17: 4 | V17: 7 | W17: 9
A18: 8 | B18: MEB21012 | C18: YUSUF ALI | E18: 5 | F18: 8.5 | J18: 13 | K18: 8 | O18: 3 | P18: 2 | Q18: 10 | R18: 5 | T18: 2 | U18: 3 | V18: 6 | W18: 7
A19: 9 | B19: MEB21013 | C19: MUSKAN BORGOHAIN | E19: 6 | F19: 8.5 | J19: 15 | K19: 10 | O19: 3 | P19: 2 | Q19: 11.5 | R19: 5 | T19: 2 | U19: 4 | V19: 8 | W19: 10.5
A20: 10 | B20: MEB21014 | C20: SARFARAZ SAMIM HAQUE | E20: 8 | F20: 13 | J20: 14 | K20: 9 | O20: 3 | P20: 2 | Q20: 11 | R20: 6 | T20: 3 | U20: 5 | V20: 10 | W20: 12
A21: 11 | B21: MEB21016 | C21: ABHRAKIRAN DAS | E21: 7 | F21: 11 | J21: 14 | K21: 9 | O21: 1 | P21: 1 | Q21: 4.5 | R21: 2 | T21: 1 | U21: 2 | V21: 3 | W21: 3
A22: 12 | B22: MEB21020 | C22: ZAHEED AKHTAR | E22: 7 | F22: 9.5 | J22: 13 | K22: 8 | O22: 3 | P22: 2 | Q22: 11 | R22: 5 | T22: 2 | U22: 3 | V22: 6 | W22: 7.5
A23: 13 | B23: MEB21021 | C23: DHYANABH SAIKIA | E23: 6 | F23: 10 | J23: 11 | K23: 8 | O23: 3 | P23: 2 | Q23: 9 | R23: 5 | T23: 2 | U23: 3 | V23: 7 | W23: 7.5
... A65: 55 | B65: MEB20050 | C65: LALIT PATIDAR | E65: 5 | F65: 8.5 | J65: 14 | K65: 9 | O65: 2 | P65: 1 | Q65: 7.5 | R65: 4 | T65: 1 | U65: 3 | V65: 5 | W65: 6
A66: 56
A67: 57
A68: 58
A69: 59
A70: 60
A71: 61
A72: 70
A73: 71
A74: 72
A75: 73
A76: 74
A77: 75
... A122: 120
J123: ATTAINMENT TABLE | K123: ABSENTEE+NOT ATTEMPT | Y123: =IF(CO_ATTAINMENT!Y131="","", CO_ATTAINMENT!Y131) -> 0 | Z123: =IF(CO_ATTAINMENT!Z131="","", CO_ATTAINMENT!Z131) -> 0 | AA123: =IF(CO_ATTAINMENT!AA131="","", CO_ATTAINMENT!AA131) -> 0 | AB123: =IF(CO_ATTAINMENT!AB131="","", CO_ATTAINMENT!AB131) -> 0 | AC123: =IF(CO_ATTAINMENT!AC131="","", CO_ATTAINMENT!AC131) -> 0 | AD123: =IF(CO_ATTAINMENT!AD131="","", CO_ATTAINMENT!AD131)
B124: CO ATTAINMENT in 3.0 POINT Scale | K124: PRESENT STUDENT OR ATTEMPT | Y124: =IF(CO_ATTAINMENT!Y132="","", CO_ATTAINMENT!Y132) -> 63 | Z124: =IF(CO_ATTAINMENT!Z132="","", CO_ATTAINMENT!Z132) -> 63 | AA124: =IF(CO_ATTAINMENT!AA132="","", CO_ATTAINMENT!AA132) -> 63 | AB124: =IF(CO_ATTAINMENT!AB132="","", CO_ATTAINMENT!AB132) -> 63 | AC124: =IF(CO_ATTAINMENT!AC132="","", CO_ATTAINMENT!AC132) -> 63 | AD124: =IF(CO_ATTAINMENT!AD132="","", CO_ATTAINMENT!AD132)
K125: NO. OF STUDENTS SECURE MARKS > THRESHOLD % FOR CO ATTAINMENT | Y125: =IF(Y$10="","",COUNTIF(Y$11:Y$122,">="&$N$1)) -> 1 | Z125: =IF(CO_ATTAINMENT!Z133="","", CO_ATTAINMENT!Z133) -> 39 | AA125: =IF(CO_ATTAINMENT!AA133="","", CO_ATTAINMENT!AA133) -> 23 | AB125: =IF(CO_ATTAINMENT!AB133="","", CO_ATTAINMENT!AB133) -> 2 | AC125: =IF(CO_ATTAINMENT!AC133="","", CO_ATTAINMENT!AC133) -> 2 | AD125: =IF(CO_ATTAINMENT!AD133="","", CO_ATTAINMENT!AD133)
...

Sheet CO_ATTAINMENT
A1: ATTAINMENT CRITERIA | C1: =IF('INTERACTION-PAGE'!C1="","",'INTERACTION-PAGE'!C1) -> 70 | E1: =IF('INTERACTION-PAGE'!E1="","",'INTERACTION-PAGE'!E1) -> 3 | G1: PASSING MARKS (%) | N1: =IF('INTERACTION-PAGE'!N1="","",'INTERACTION-PAGE'!N1) -> 30
C2: =IF('INTERACTION-PAGE'!C2="","",'INTERACTION-PAGE'!C2) -> 60 | E2: =IF('INTERACTION-PAGE'!E2="","",'INTERACTION-PAGE'!E2) -> 2 | F2: =C1-C2 -> 10 | G2: Threshold % for CO attainment | N2: =IF('INTERACTION-PAGE'!N2="","",'INTERACTION-PAGE'!N2) -> 60
C3: =IF('INTERACTION-PAGE'!C3="","",'INTERACTION-PAGE'!C3) -> 50 | E3: =IF('INTERACTION-PAGE'!E3="","",'INTERACTION-PAGE'!E3) -> 1 | F3: =C2-C3 -> 10 | G3: Please fill "AB" for Absent and "UR" for Unregistered candidate(s)
A4: =IF('INTERACTION-PAGE'!A4="","",'INTERACTION-PAGE'!A4) -> TEZPUR UNIVERSITY
A5: Faculty Name: | C5: =IF('INTERACTION-PAGE'!C5="","",'INTERACTION-PAGE'!C5) -> Dr S. S. Satapathy | G5: BRANCH | I5: =IF('INTERACTION-PAGE'!I5="","",'INTERACTION-PAGE'!I5) -> Mechanical Engineering | N5: Course: | Z5: =IF('INTERACTION-PAGE'!Z5="","",'INTERACTION-PAGE'!Z5) -> Introductory Computing
A6: Programme: | C6: =IF('INTERACTION-PAGE'!C6="","",'INTERACTION-PAGE'!C6) -> B. Tech | E6: YEAR | G6: =IF('INTERACTION-PAGE'!G6="","",'INTERACTION-PAGE'!G6) -> I | I6: SEM | K6: =IF('INTERACTION-PAGE'!K6="","",'INTERACTION-PAGE'!K6) -> II | M6: Course Code: | Z6: =IF('INTERACTION-PAGE'!Z6="","",'INTERACTION-PAGE'!Z6) -> CO103 | AB6: SESSION | AD6: =IF('INTERACTION-PAGE'!AD6="","",'INTERACTION-PAGE'!AD6) -> 2021-22 | AF6: II
E7: Assessment of Test -I | J7: Assessment of Test -II | O7: Assessment for Mid Term Exam | T7: Assessment of End Term Exam | AF7: III
A8: S. No. | B8: Roll No. | C8: Name of Student | D8: ABSENTEE RECORD | E8: Maximum Marks | I8: =SUM(E10:I10) -> 25 | J8: Maximum Marks | N8: =SUM(J10:N10) -> 25 | O8: Maximum Marks | S8: =SUM(O10:S10) -> 40 | T8: Maximum Marks | X8: =SUM(T10:X10) -> 60 | Y8: TOTAL | Z8: CO1 | AA8: CO2 | AB8: CO3 | AC8: CO4 | AD8: CO5 | AE8: ΣCO | AF8: IV
E9: CO1 | F9: CO2 | G9: CO3 | H9: CO4 | I9: CO5 | J9: CO1 | K9: CO2 | L9: CO3 | M9: CO4 | N9: CO5 | O9: CO1 | P9: CO2 | Q9: CO3 | R9: CO4 | S9: CO5 | T9: CO1 | U9: CO2 | V9: CO3 | W9: CO4 | X9: CO5 | Y9: % | Z9: % | AA9: % | AB9: % | AC9: % | AD9: % | AE9: %
C10: CO WISE MAXIMUM MARKS | D10: "AB" or "UR" | E10: =IF('INTERACTION-PAGE'!E10="","",'INTERACTION-PAGE'!E10) -> 10 | F10: =IF('INTERACTION-PAGE'!F10="","",'INTERACTION-PAGE'!F10) -> 15 | G10: =IF('INTERACTION-PAGE'!G10="","",'INTERACTION-PAGE'!G10) -> 0 | H10: =IF('INTERACTION-PAGE'!H10="","",'INTERACTION-PAGE'!H10) -> 0 | I10: =IF('INTERACTION-PAGE'!I10="","",'INTERACTION-PAGE'!I10) -> 0 | J10: =IF('INTERACTION-PAGE'!J10="","",'INTERACTION-PAGE'!J10) -> 15 | K10: =IF('INTERACTION-PAGE'!K10="","",'INTERACTION-PAGE'!K10) -> 10 | L10: =IF('INTERACTION-PAGE'!L10="","",'INTERACTION-PAGE'!L10) -> 0 | ... X10: =IF('INTERACTION-PAGE'!X10="","",'INTERACTION-PAGE'!X10) -> 0 | Y10: =100 * SUM(E10:X10) / SUM(I$8, N$8, S$8, X$8) -> 100 | Z10: =IF((E10+J10+O10+T10)>0,100,"") -> 100 | AA10: =IF((F10+K10+P10+U10)>0,100,"") -> 100 | AB10: =IF((G10+L10+Q10+V10)>0,100,"") -> 100 | AC10: =IF((H10+M10+R10+W10)>0,100,"") -> 100 | AD10: =IF((I10+N10+S10+X10)>0,100,"") | AE10: =IFERROR(AVERAGE(Z10:AD10),"") -> 100
A11: 1 | B11: =IF('INTERACTION-PAGE'!B11="","",'INTERACTION-PAGE'!B11) -> MEB21001 | C11: =IF('INTERACTION-PAGE'!C11="","",'INTERACTION-PAGE'!C11) -> NEKIBUR RAHMAN | D11: =IF('INTERACTION-PAGE'!D11="","",'INTERACTION-PAGE'!D11) | E11: =IF('INTERACTION-PAGE'!E11="","",'INTERACTION-PAGE'!E11) -> 5 | F11: =IF('INTERACTION-PAGE'!F11="","",'INTERACTION-PAGE'!F11) -> 7 | G11: =IF('INTERACTION-PAGE'!G11="","",'INTERACTION-PAGE'!G11) | H11: =IF('INTERACTION-PAGE'!H11="","",'INTERACTION-PAGE'!H11) | I11: =IF('INTERACTION-PAGE'!I11="","",'INTERACTION-PAGE'!I11) | ... X11: =IF('INTERACTION-PAGE'!X11="","",'INTERACTION-PAGE'!X11) | Y11: =IF(OR( $B11="", $B11="AB", $B11="UR", $C11="", $C11="AB", $C11="UR", $D11="AB", $D11="UR"),"",(IF(OR(I$8>0,N$8>0,S$8>0,X$8>0),(100*SUM($E11:$X11)/(I$8+N$8+S$8+X$8))," "))) -> 44.666667 | Z11: =IF(OR( $B11="", $B11="AB", $B11="UR", $C11="", $C11="AB", $C11="UR", $D11="AB", $D11="UR"),"",(IF(OR(E$10>0,J$10>0,O$10>0,T$10>0),(Z$10*(IF(AND(E$10>0), IF(OR(E11="", E11="AB",E11="UR"),0,E11),0) +IF(AND(J$10>0), IF(OR(J11="",J11="AB",J11=""),0,J11),0)+IF(AND(O$10>0), IF(OR(O11="", O11="AB",O11="UR"),0,O11),0)+IF(AND(T$10>0), IF(OR(T11="",T11="AB",T11="UR"),0,T11),0))/(E$10+J$10+O$10+T$10))," "))) -> 61.111111 | AA11: =IF(OR( $B11="", $B11="AB", $B11="UR", $C11="", $C11="AB", $C11="UR", $D11="AB", $D11="UR"),"",(IF(OR(F$10>0,K$10>0,P$10>0,U$10>0),(AA$10*(IF(AND(F$10>0), IF(OR(F11="", F11="AB",F11="UR"),0,F11),0) +IF(AND(K$10>0), IF(OR(K11="",K11="AB",K11=""),0,K11),0)+IF(AND(P$10>0), IF(OR(P11="", P11="AB",P11="UR"),0,P11),0)+IF(AND(U$10>0), IF(OR(U11="",U11="AB",U11="UR"),0,U11),0))/(F$10+K$10+P$10+U$10))," "))) -> 51.282051 | AB11: =IF(OR( $B11="", $B11="AB", $B11="UR", $C11="", $C11="AB", $C11="UR", $D11="AB", $D11="UR"),"",(IF(OR(G$10>0,L$10>0,Q$10>0,V$10>0),(AB$10*(IF(AND(G$10>0), IF(OR(G11="", G11="AB",G11="UR"),0,G11),0) +IF(AND(L$10>0), IF(OR(L11="",L11="AB",L11=""),0,L11),0)+IF(AND(Q$10>0), IF(OR(Q11="", Q11="AB",Q11="UR"),0,Q11),0)+IF(AND(V$10>0), IF(OR(V11="",V11="AB",V11="UR"),0,V11),0))/(G$10+L$10+Q$10+V$10))," "))) -> 35 | AC11: =IF(OR( $B11="", $B11="AB", $B11="UR", $C11="", $C11="AB", $C11="UR", $D11="AB", $D11="UR"),"",(IF(OR(H$10>0,M$10>0,R$10>0,W$10>0),(AC$10*(IF(AND(H$10>0), IF(OR(H11="", H11="AB",H11="UR"),0,H11),0) +IF(AND(M$10>0), IF(OR(M11="",M11="AB",M11=""),0,M11),0)+IF(AND(R$10>0), IF(OR(R11="", R11="AB",R11="UR"),0,R11),0)+IF(AND(W$10>0), IF(OR(W11="",W11="AB",W11="UR"),0,W11),0))/(H$10+M$10+R$10+W$10))," "))) -> 31.428571 | AD11: =IF(OR( $B11="", $B11="AB", $B11="UR", $C11="", $C11="AB", $C11="UR", $D11="AB", $D11="UR"),"",(IF(OR(I$10>0,N$10>0,S$10>0,X$10>0),(AD$10*(IF(AND(I$10>0), IF(OR(I11="", I11="AB",I11="UR"),0,I11),0) +IF(AND(N$10>0), IF(OR(N11="",N11="AB",N11=""),0,N11),0)+IF(AND(S$10>0), IF(OR(S11="", S11="AB",S11="UR"),0,S11),0)+IF(AND(X$10>0), IF(OR(X11="",X11="AB",X11="UR"),0,X11),0))/(I$10+N$10+S$10+X$10))," "))) | AE11: =IF(C11="","",IFERROR(AVERAGE(Z11:AD11),"")) -> 44.705433
A12: 2 | B12: =IF('INTERACTION-PAGE'!B12="","",'INTERACTION-PAGE'!B12) -> MEB21003 | C12: =IF('INTERACTION-PAGE'!C12="","",'INTERACTION-PAGE'!C12) -> NILOATPAL MAZUMDER | D12: =IF('INTERACTION-PAGE'!D12="","",'INTERACTION-PAGE'!D12) | E12: =IF('INTERACTION-PAGE'!E12="","",'INTERACTION-PAGE'!E12) -> 8 | F12: =IF('INTERACTION-PAGE'!F12="","",'INTERACTION-PAGE'!F12) -> 13 | G12: =IF('INTERACTION-PAGE'!G12="","",'INTERACTION-PAGE'!G12) | H12: =IF('INTERACTION-PAGE'!H12="","",'INTERACTION-PAGE'!H12) | I12: =IF('INTERACTION-PAGE'!I12="","",'INTERACTION-PAGE'!I12) | ... X12: =IF('INTERACTION-PAGE'!X12="","",'INTERACTION-PAGE'!X12) | Y12: =IF(OR( $B12="", $B12="AB", $B12="UR", $C12="", $C12="AB", $C12="UR", $D12="AB", $D12="UR"),"",(IF(OR(I$8>0,N$8>0,S$8>0,X$8>0),(100*SUM(E12:X12)/(I$8+N$8+S$8+X$8))," "))) -> 66 | Z12: =IF(OR( $B12="", $B12="AB", $B12="UR", $C12="", $C12="AB", $C12="UR", $D12="AB", $D12="UR"),"",(IF(OR(E$10>0,J$10>0,O$10>0,T$10>0),(Z$10*(IF(AND(E$10>0), IF(OR(E12="", E12="AB",E12="UR"),0,E12),0) +IF(AND(J$10>0), IF(OR(J12="",J12="AB",J12=""),0,J12),0)+IF(AND(O$10>0), IF(OR(O12="", O12="AB",O12="UR"),0,O12),0)+IF(AND(T$10>0), IF(OR(T12="",T12="AB",T12="UR"),0,T12),0))/(E$10+J$10+O$10+T$10))," "))) -> 77.777778 | AA12: =IF(OR( $B12="", $B12="AB", $B12="UR", $C12="", $C12="AB", $C12="UR", $D12="AB", $D12="UR"),"",(IF(OR(F$10>0,K$10>0,P$10>0,U$10>0),(AA$10*(IF(AND(F$10>0), IF(OR(F12="", F12="AB",F12="UR"),0,F12),0) +IF(AND(K$10>0), IF(OR(K12="",K12="AB",K12=""),0,K12),0)+IF(AND(P$10>0), IF(OR(P12="", P12="AB",P12="UR"),0,P12),0)+IF(AND(U$10>0), IF(OR(U12="",U12="AB",U12="UR"),0,U12),0))/(F$10+K$10+P$10+U$10))," "))) -> 74.358974 | AB12: =IF(OR( $B12="", $B12="AB", $B12="UR", $C12="", $C12="AB", $C12="UR", $D12="AB", $D12="UR"),"",(IF(OR(G$10>0,L$10>0,Q$10>0,V$10>0),(AB$10*(IF(AND(G$10>0), IF(OR(G12="", G12="AB",G12="UR"),0,G12),0) +IF(AND(L$10>0), IF(OR(L12="",L12="AB",L12=""),0,L12),0)+IF(AND(Q$10>0), IF(OR(Q12="", Q12="AB",Q12="UR"),0,Q12),0)+IF(AND(V$10>0), IF(OR(V12="",V12="AB",V12="UR"),0,V12),0))/(G$10+L$10+Q$10+V$10))," "))) -> 57.5 | AC12: =IF(OR( $B12="", $B12="AB", $B12="UR", $C12="", $C12="AB", $C12="UR", $D12="AB", $D12="UR"),"",(IF(OR(H$10>0,M$10>0,R$10>0,W$10>0),(AC$10*(IF(AND(H$10>0), IF(OR(H12="", H12="AB",H12="UR"),0,H12),0) +IF(AND(M$10>0), IF(OR(M12="",M12="AB",M12=""),0,M12),0)+IF(AND(R$10>0), IF(OR(R12="", R12="AB",R12="UR"),0,R12),0)+IF(AND(W$10>0), IF(OR(W12="",W12="AB",W12="UR"),0,W12),0))/(H$10+M$10+R$10+W$10))," "))) -> 54.285714 | AD12: =IF(OR( $B12="", $B12="AB", $B12="UR", $C12="", $C12="AB", $C12="UR", $D12="AB", $D12="UR"),"",(IF(OR(I$10>0,N$10>0,S$10>0,X$10>0),(AD$10*(IF(AND(I$10>0), IF(OR(I12="", I12="AB",I12="UR"),0,I12),0) +IF(AND(N$10>0), IF(OR(N12="",N12="AB",N12=""),0,N12),0)+IF(AND(S$10>0), IF(OR(S12="", S12="AB",S12="UR"),0,S12),0)+IF(AND(X$10>0), IF(OR(X12="",X12="AB",X12="UR"),0,X12),0))/(I$10+N$10+S$10+X$10))," "))) | AE12: =IF(C12="","",IFERROR(AVERAGE(Z12:AD12),"")) -> 65.980617
A13: 3 | B13: =IF('INTERACTION-PAGE'!B13="","",'INTERACTION-PAGE'!B13) -> MEB21004 | C13: =IF('INTERACTION-PAGE'!C13="","",'INTERACTION-PAGE'!C13) -> SHAHIL ALI MOSSADDIQUE | D13: =IF('INTERACTION-PAGE'!D13="","",'INTERACTION-PAGE'!D13) | E13: =IF('INTERACTION-PAGE'!E13="","",'INTERACTION-PAGE'!E13) -> 5 | F13: =IF('INTERACTION-PAGE'!F13="","",'INTERACTION-PAGE'!F13) -> 6.5 | G13: =IF('INTERACTION-PAGE'!G13="","",'INTERACTION-PAGE'!G13) | H13: =IF('INTERACTION-PAGE'!H13="","",'INTERACTION-PAGE'!H13) | I13: =IF('INTERACTION-PAGE'!I13="","",'INTERACTION-PAGE'!I13) | ... X13: =IF('INTERACTION-PAGE'!X13="","",'INTERACTION-PAGE'!X13) | Y13: =IF(OR( $B13="", $B13="AB", $B13="UR", $C13="", $C13="AB", $C13="UR", $D13="AB", $D13="UR"),"",(IF(OR(I$8>0,N$8>0,S$8>0,X$8>0),(100*SUM(E13:X13)/(I$8+N$8+S$8+X$8))," "))) -> 37 | Z13: =IF(OR( $B13="", $B13="AB", $B13="UR", $C13="", $C13="AB", $C13="UR", $D13="AB", $D13="UR"),"",(IF(OR(E$10>0,J$10>0,O$10>0,T$10>0),(Z$10*(IF(AND(E$10>0), IF(OR(E13="", E13="AB",E13="UR"),0,E13),0) +IF(AND(J$10>0), IF(OR(J13="",J13="AB",J13=""),0,J13),0)+IF(AND(O$10>0), IF(OR(O13="", O13="AB",O13="UR"),0,O13),0)+IF(AND(T$10>0), IF(OR(T13="",T13="AB",T13="UR"),0,T13),0))/(E$10+J$10+O$10+T$10))," "))) -> 61.111111 | AA13: =IF(OR( $B13="", $B13="AB", $B13="UR", $C13="", $C13="AB", $C13="UR", $D13="AB", $D13="UR"),"",(IF(OR(F$10>0,K$10>0,P$10>0,U$10>0),(AA$10*(IF(AND(F$10>0), IF(OR(F13="", F13="AB",F13="UR"),0,F13),0) +IF(AND(K$10>0), IF(OR(K13="",K13="AB",K13=""),0,K13),0)+IF(AND(P$10>0), IF(OR(P13="", P13="AB",P13="UR"),0,P13),0)+IF(AND(U$10>0), IF(OR(U13="",U13="AB",U13="UR"),0,U13),0))/(F$10+K$10+P$10+U$10))," "))) -> 47.435897 | AB13: =IF(OR( $B13="", $B13="AB", $B13="UR", $C13="", $C13="AB", $C13="UR", $D13="AB", $D13="UR"),"",(IF(OR(G$10>0,L$10>0,Q$10>0,V$10>0),(AB$10*(IF(AND(G$10>0), IF(OR(G13="", G13="AB",G13="UR"),0,G13),0) +IF(AND(L$10>0), IF(OR(L13="",L13="AB",L13=""),0,L13),0)+IF(AND(Q$10>0), IF(OR(Q13="", Q13="AB",Q13="UR"),0,Q13),0)+IF(AND(V$10>0), IF(OR(V13="",V13="AB",V13="UR"),0,V13),0))/(G$10+L$10+Q$10+V$10))," "))) -> 22.5 | AC13: =IF(OR( $B13="", $B13="AB", $B13="UR", $C13="", $C13="AB", $C13="UR", $D13="AB", $D13="UR"),"",(IF(OR(H$10>0,M$10>0,R$10>0,W$10>0),(AC$10*(IF(AND(H$10>0), IF(OR(H13="", H13="AB",H13="UR"),0,H13),0) +IF(AND(M$10>0), IF(OR(M13="",M13="AB",M13=""),0,M13),0)+IF(AND(R$10>0), IF(OR(R13="", R13="AB",R13="UR"),0,R13),0)+IF(AND(W$10>0), IF(OR(W13="",W13="AB",W13="UR"),0,W13),0))/(H$10+M$10+R$10+W$10))," "))) -> 17.142857 | AD13: =IF(OR( $B13="", $B13="AB", $B13="UR", $C13="", $C13="AB", $C13="UR", $D13="AB", $D13="UR"),"",(IF(OR(I$10>0,N$10>0,S$10>0,X$10>0),(AD$10*(IF(AND(I$10>0), IF(OR(I13="", I13="AB",I13="UR"),0,I13),0) +IF(AND(N$10>0), IF(OR(N13="",N13="AB",N13=""),0,N13),0)+IF(AND(S$10>0), IF(OR(S13="", S13="AB",S13="UR"),0,S13),0)+IF(AND(X$10>0), IF(OR(X13="",X13="AB",X13="UR"),0,X13),0))/(I$10+N$10+S$10+X$10))," "))) | AE13: =IF(C13="","",IFERROR(AVERAGE(Z13:AD13),"")) -> 37.047466
A14: 4 | B14: =IF('INTERACTION-PAGE'!B14="","",'INTERACTION-PAGE'!B14) -> MEB21005 | C14: =IF('INTERACTION-PAGE'!C14="","",'INTERACTION-PAGE'!C14) -> CHANDRAK BHATTACHARJEE | D14: =IF('INTERACTION-PAGE'!D14="","",'INTERACTION-PAGE'!D14) | E14: =IF('INTERACTION-PAGE'!E14="","",'INTERACTION-PAGE'!E14) -> 8 | F14: =IF('INTERACTION-PAGE'!F14="","",'INTERACTION-PAGE'!F14) -> 11.5 | G14: =IF('INTERACTION-PAGE'!G14="","",'INTERACTION-PAGE'!G14) | H14: =IF('INTERACTION-PAGE'!H14="","",'INTERACTION-PAGE'!H14) | I14: =IF('INTERACTION-PAGE'!I14="","",'INTERACTION-PAGE'!I14) | ... X14: =IF('INTERACTION-PAGE'!X14="","",'INTERACTION-PAGE'!X14) | Y14: =IF(OR( $B14="", $B14="AB", $B14="UR", $C14="", $C14="AB", $C14="UR", $D14="AB", $D14="UR"),"",(IF(OR(I$8>0,N$8>0,S$8>0,X$8>0),(100*SUM(E14:X14)/(I$8+N$8+S$8+X$8))," "))) -> 63.333333 | Z14: =IF(OR( $B14="", $B14="AB", $B14="UR", $C14="", $C14="AB", $C14="UR", $D14="AB", $D14="UR"),"",(IF(OR(E$10>0,J$10>0,O$10>0,T$10>0),(Z$10*(IF(AND(E$10>0), IF(OR(E14="", E14="AB",E14="UR"),0,E14),0) +IF(AND(J$10>0), IF(OR(J14="",J14="AB",J14=""),0,J14),0)+IF(AND(O$10>0), IF(OR(O14="", O14="AB",O14="UR"),0,O14),0)+IF(AND(T$10>0), IF(OR(T14="",T14="AB",T14="UR"),0,T14),0))/(E$10+J$10+O$10+T$10))," "))) -> 77.777778 | AA14: =IF(OR( $B14="", $B14="AB", $B14="UR", $C14="", $C14="AB", $C14="UR", $D14="AB", $D14="UR"),"",(IF(OR(F$10>0,K$10>0,P$10>0,U$10>0),(AA$10*(IF(AND(F$10>0), IF(OR(F14="", F14="AB",F14="UR"),0,F14),0) +IF(AND(K$10>0), IF(OR(K14="",K14="AB",K14=""),0,K14),0)+IF(AND(P$10>0), IF(OR(P14="", P14="AB",P14="UR"),0,P14),0)+IF(AND(U$10>0), IF(OR(U14="",U14="AB",U14="UR"),0,U14),0))/(F$10+K$10+P$10+U$10))," "))) -> 67.948718 | AB14: =IF(OR( $B14="", $B14="AB", $B14="UR", $C14="", $C14="AB", $C14="UR", $D14="AB", $D14="UR"),"",(IF(OR(G$10>0,L$10>0,Q$10>0,V$10>0),(AB$10*(IF(AND(G$10>0), IF(OR(G14="", G14="AB",G14="UR"),0,G14),0) +IF(AND(L$10>0), IF(OR(L14="",L14="AB",L14=""),0,L14),0)+IF(AND(Q$10>0), IF(OR(Q14="", Q14="AB",Q14="UR"),0,Q14),0)+IF(AND(V$10>0), IF(OR(V14="",V14="AB",V14="UR"),0,V14),0))/(G$10+L$10+Q$10+V$10))," "))) -> 56.25 | AC14: =IF(OR( $B14="", $B14="AB", $B14="UR", $C14="", $C14="AB", $C14="UR", $D14="AB", $D14="UR"),"",(IF(OR(H$10>0,M$10>0,R$10>0,W$10>0),(AC$10*(IF(AND(H$10>0), IF(OR(H14="", H14="AB",H14="UR"),0,H14),0) +IF(AND(M$10>0), IF(OR(M14="",M14="AB",M14=""),0,M14),0)+IF(AND(R$10>0), IF(OR(R14="", R14="AB",R14="UR"),0,R14),0)+IF(AND(W$10>0), IF(OR(W14="",W14="AB",W14="UR"),0,W14),0))/(H$10+M$10+R$10+W$10))," "))) -> 51.428571 | AD14: =IF(OR( $B14="", $B14="AB", $B14="UR", $C14="", $C14="AB", $C14="UR", $D14="AB", $D14="UR"),"",(IF(OR(I$10>0,N$10>0,S$10>0,X$10>0),(AD$10*(IF(AND(I$10>0), IF(OR(I14="", I14="AB",I14="UR"),0,I14),0) +IF(AND(N$10>0), IF(OR(N14="",N14="AB",N14=""),0,N14),0)+IF(AND(S$10>0), IF(OR(S14="", S14="AB",S14="UR"),0,S14),0)+IF(AND(X$10>0), IF(OR(X14="",X14="AB",X14="UR"),0,X14),0))/(I$10+N$10+S$10+X$10))," "))) | AE14: =IF(C14="","",IFERROR(AVERAGE(Z14:AD14),"")) -> 63.351267
A15: 5 | B15: =IF('INTERACTION-PAGE'!B15="","",'INTERACTION-PAGE'!B15) -> MEB21006 | C15: =IF('INTERACTION-PAGE'!C15="","",'INTERACTION-PAGE'!C15) -> SIVAM KARMAKAR | D15: =IF('INTERACTION-PAGE'!D15="","",'INTERACTION-PAGE'!D15) | E15: =IF('INTERACTION-PAGE'!E15="","",'INTERACTION-PAGE'!E15) -> 9 | F15: =IF('INTERACTION-PAGE'!F15="","",'INTERACTION-PAGE'!F15) -> 12.5 | G15: =IF('INTERACTION-PAGE'!G15="","",'INTERACTION-PAGE'!G15) | H15: =IF('INTERACTION-PAGE'!H15="","",'INTERACTION-PAGE'!H15) | I15: =IF('INTERACTION-PAGE'!I15="","",'INTERACTION-PAGE'!I15) | ... X15: =IF('INTERACTION-PAGE'!X15="","",'INTERACTION-PAGE'!X15) | Y15: =IF(OR( $B15="", $B15="AB", $B15="UR", $C15="", $C15="AB", $C15="UR", $D15="AB", $D15="UR"),"",(IF(OR(I$8>0,N$8>0,S$8>0,X$8>0),(100*SUM(E15:X15)/(I$8+N$8+S$8+X$8))," "))) -> 62.666667 | Z15: =IF(OR( $B15="", $B15="AB", $B15="UR", $C15="", $C15="AB", $C15="UR", $D15="AB", $D15="UR"),"",(IF(OR(E$10>0,J$10>0,O$10>0,T$10>0),(Z$10*(IF(AND(E$10>0), IF(OR(E15="", E15="AB",E15="UR"),0,E15),0) +IF(AND(J$10>0), IF(OR(J15="",J15="AB",J15=""),0,J15),0)+IF(AND(O$10>0), IF(OR(O15="", O15="AB",O15="UR"),0,O15),0)+IF(AND(T$10>0), IF(OR(T15="",T15="AB",T15="UR"),0,T15),0))/(E$10+J$10+O$10+T$10))," "))) -> 72.222222 | AA15: =IF(OR( $B15="", $B15="AB", $B15="UR", $C15="", $C15="AB", $C15="UR", $D15="AB", $D15="UR"),"",(IF(OR(F$10>0,K$10>0,P$10>0,U$10>0),(AA$10*(IF(AND(F$10>0), IF(OR(F15="", F15="AB",F15="UR"),0,F15),0) +IF(AND(K$10>0), IF(OR(K15="",K15="AB",K15=""),0,K15),0)+IF(AND(P$10>0), IF(OR(P15="", P15="AB",P15="UR"),0,P15),0)+IF(AND(U$10>0), IF(OR(U15="",U15="AB",U15="UR"),0,U15),0))/(F$10+K$10+P$10+U$10))," "))) -> 70.512821 | AB15: =IF(OR( $B15="", $B15="AB", $B15="UR", $C15="", $C15="AB", $C15="UR", $D15="AB", $D15="UR"),"",(IF(OR(G$10>0,L$10>0,Q$10>0,V$10>0),(AB$10*(IF(AND(G$10>0), IF(OR(G15="", G15="AB",G15="UR"),0,G15),0) +IF(AND(L$10>0), IF(OR(L15="",L15="AB",L15=""),0,L15),0)+IF(AND(Q$10>0), IF(OR(Q15="", Q15="AB",Q15="UR"),0,Q15),0)+IF(AND(V$10>0), IF(OR(V15="",V15="AB",V15="UR"),0,V15),0))/(G$10+L$10+Q$10+V$10))," "))) -> 56.25 | AC15: =IF(OR( $B15="", $B15="AB", $B15="UR", $C15="", $C15="AB", $C15="UR", $D15="AB", $D15="UR"),"",(IF(OR(H$10>0,M$10>0,R$10>0,W$10>0),(AC$10*(IF(AND(H$10>0), IF(OR(H15="", H15="AB",H15="UR"),0,H15),0) +IF(AND(M$10>0), IF(OR(M15="",M15="AB",M15=""),0,M15),0)+IF(AND(R$10>0), IF(OR(R15="", R15="AB",R15="UR"),0,R15),0)+IF(AND(W$10>0), IF(OR(W15="",W15="AB",W15="UR"),0,W15),0))/(H$10+M$10+R$10+W$10))," "))) -> 51.428571 | AD15: =IF(OR( $B15="", $B15="AB", $B15="UR", $C15="", $C15="AB", $C15="UR", $D15="AB", $D15="UR"),"",(IF(OR(I$10>0,N$10>0,S$10>0,X$10>0),(AD$10*(IF(AND(I$10>0), IF(OR(I15="", I15="AB",I15="UR"),0,I15),0) +IF(AND(N$10>0), IF(OR(N15="",N15="AB",N15=""),0,N15),0)+IF(AND(S$10>0), IF(OR(S15="", S15="AB",S15="UR"),0,S15),0)+IF(AND(X$10>0), IF(OR(X15="",X15="AB",X15="UR"),0,X15),0))/(I$10+N$10+S$10+X$10))," "))) | AE15: =IF(C15="","",IFERROR(AVERAGE(Z15:AD15),"")) -> 62.603404
A16: 6 | B16: =IF('INTERACTION-PAGE'!B16="","",'INTERACTION-PAGE'!B16) -> MEB21007 | C16: =IF('INTERACTION-PAGE'!C16="","",'INTERACTION-PAGE'!C16) -> CHIRANJEEV SHUBHAM | D16: =IF('INTERACTION-PAGE'!D16="","",'INTERACTION-PAGE'!D16) | E16: =IF('INTERACTION-PAGE'!E16="","",'INTERACTION-PAGE'!E16) -> 6 | F16: =IF('INTERACTION-PAGE'!F16="","",'INTERACTION-PAGE'!F16) -> 9 | G16: =IF('INTERACTION-PAGE'!G16="","",'INTERACTION-PAGE'!G16) | H16: =IF('INTERACTION-PAGE'!H16="","",'INTERACTION-PAGE'!H16) | I16: =IF('INTERACTION-PAGE'!I16="","",'INTERACTION-PAGE'!I16) | ... X16: =IF('INTERACTION-PAGE'!X16="","",'INTERACTION-PAGE'!X16) | Y16: =IF(OR( $B16="", $B16="AB", $B16="UR", $C16="", $C16="AB", $C16="UR", $D16="AB", $D16="UR"),"",(IF(OR(I$8>0,N$8>0,S$8>0,X$8>0),(100*SUM(E16:X16)/(I$8+N$8+S$8+X$8))," "))) -> 53.333333 | Z16: =IF(OR( $B16="", $B16="AB", $B16="UR", $C16="", $C16="AB", $C16="UR", $D16="AB", $D16="UR"),"",(IF(OR(E$10>0,J$10>0,O$10>0,T$10>0),(Z$10*(IF(AND(E$10>0), IF(OR(E16="", E16="AB",E16="UR"),0,E16),0) +IF(AND(J$10>0), IF(OR(J16="",J16="AB",J16=""),0,J16),0)+IF(AND(O$10>0), IF(OR(O16="", O16="AB",O16="UR"),0,O16),0)+IF(AND(T$10>0), IF(OR(T16="",T16="AB",T16="UR"),0,T16),0))/(E$10+J$10+O$10+T$10))," "))) -> 69.444444 | AA16: =IF(OR( $B16="", $B16="AB", $B16="UR", $C16="", $C16="AB", $C16="UR", $D16="AB", $D16="UR"),"",(IF(OR(F$10>0,K$10>0,P$10>0,U$10>0),(AA$10*(IF(AND(F$10>0), IF(OR(F16="", F16="AB",F16="UR"),0,F16),0) +IF(AND(K$10>0), IF(OR(K16="",K16="AB",K16=""),0,K16),0)+IF(AND(P$10>0), IF(OR(P16="", P16="AB",P16="UR"),0,P16),0)+IF(AND(U$10>0), IF(OR(U16="",U16="AB",U16="UR"),0,U16),0))/(F$10+K$10+P$10+U$10))," "))) -> 61.538462 | AB16: =IF(OR( $B16="", $B16="AB", $B16="UR", $C16="", $C16="AB", $C16="UR", $D16="AB", $D16="UR"),"",(IF(OR(G$10>0,L$10>0,Q$10>0,V$10>0),(AB$10*(IF(AND(G$10>0), IF(OR(G16="", G16="AB",G16="UR"),0,G16),0) +IF(AND(L$10>0), IF(OR(L16="",L16="AB",L16=""),0,L16),0)+IF(AND(Q$10>0), IF(OR(Q16="", Q16="AB",Q16="UR"),0,Q16),0)+IF(AND(V$10>0), IF(OR(V16="",V16="AB",V16="UR"),0,V16),0))/(G$10+L$10+Q$10+V$10))," "))) -> 42.5 | AC16: =IF(OR( $B16="", $B16="AB", $B16="UR", $C16="", $C16="AB", $C16="UR", $D16="AB", $D16="UR"),"",(IF(OR(H$10>0,M$10>0,R$10>0,W$10>0),(AC$10*(IF(AND(H$10>0), IF(OR(H16="", H16="AB",H16="UR"),0,H16),0) +IF(AND(M$10>0), IF(OR(M16="",M16="AB",M16=""),0,M16),0)+IF(AND(R$10>0), IF(OR(R16="", R16="AB",R16="UR"),0,R16),0)+IF(AND(W$10>0), IF(OR(W16="",W16="AB",W16="UR"),0,W16),0))/(H$10+M$10+R$10+W$10))," "))) -> 40 | AD16: =IF(OR( $B16="", $B16="AB", $B16="UR", $C16="", $C16="AB", $C16="UR", $D16="AB", $D16="UR"),"",(IF(OR(I$10>0,N$10>0,S$10>0,X$10>0),(AD$10*(IF(AND(I$10>0), IF(OR(I16="", I16="AB",I16="UR"),0,I16),0) +IF(AND(N$10>0), IF(OR(N16="",N16="AB",N16=""),0,N16),0)+IF(AND(S$10>0), IF(OR(S16="", S16="AB",S16="UR"),0,S16),0)+IF(AND(X$10>0), IF(OR(X16="",X16="AB",X16="UR"),0,X16),0))/(I$10+N$10+S$10+X$10))," "))) | AE16: =IF(C16="","",IFERROR(AVERAGE(Z16:AD16),"")) -> 53.370727
A17: 7 | B17: =IF('INTERACTION-PAGE'!B17="","",'INTERACTION-PAGE'!B17) -> MEB21009 | C17: =IF('INTERACTION-PAGE'!C17="","",'INTERACTION-PAGE'!C17) -> OWEN RUMON GARG | D17: =IF('INTERACTION-PAGE'!D17="","",'INTERACTION-PAGE'!D17) | E17: =IF('INTERACTION-PAGE'!E17="","",'INTERACTION-PAGE'!E17) -> 7 | F17: =IF('INTERACTION-PAGE'!F17="","",'INTERACTION-PAGE'!F17) -> 11 | G17: =IF('INTERACTION-PAGE'!G17="","",'INTERACTION-PAGE'!G17) | H17: =IF('INTERACTION-PAGE'!H17="","",'INTERACTION-PAGE'!H17) | I17: =IF('INTERACTION-PAGE'!I17="","",'INTERACTION-PAGE'!I17) | ... X17: =IF('INTERACTION-PAGE'!X17="","",'INTERACTION-PAGE'!X17) | Y17: =IF(OR( $B17="", $B17="AB", $B17="UR", $C17="", $C17="AB", $C17="UR", $D17="AB", $D17="UR"),"",(IF(OR(I$8>0,N$8>0,S$8>0,X$8>0),(100*SUM(E17:X17)/(I$8+N$8+S$8+X$8))," "))) -> 55.666667 | Z17: =IF(OR( $B17="", $B17="AB", $B17="UR", $C17="", $C17="AB", $C17="UR", $D17="AB", $D17="UR"),"",(IF(OR(E$10>0,J$10>0,O$10>0,T$10>0),(Z$10*(IF(AND(E$10>0), IF(OR(E17="", E17="AB",E17="UR"),0,E17),0) +IF(AND(J$10>0), IF(OR(J17="",J17="AB",J17=""),0,J17),0)+IF(AND(O$10>0), IF(OR(O17="", O17="AB",O17="UR"),0,O17),0)+IF(AND(T$10>0), IF(OR(T17="",T17="AB",T17="UR"),0,T17),0))/(E$10+J$10+O$10+T$10))," "))) -> 72.222222 | AA17: =IF(OR( $B17="", $B17="AB", $B17="UR", $C17="", $C17="AB", $C17="UR", $D17="AB", $D17="UR"),"",(IF(OR(F$10>0,K$10>0,P$10>0,U$10>0),(AA$10*(IF(AND(F$10>0), IF(OR(F17="", F17="AB",F17="UR"),0,F17),0) +IF(AND(K$10>0), IF(OR(K17="",K17="AB",K17=""),0,K17),0)+IF(AND(P$10>0), IF(OR(P17="", P17="AB",P17="UR"),0,P17),0)+IF(AND(U$10>0), IF(OR(U17="",U17="AB",U17="UR"),0,U17),0))/(F$10+K$10+P$10+U$10))," "))) -> 66.666667 | AB17: =IF(OR( $B17="", $B17="AB", $B17="UR", $C17="", $C17="AB", $C17="UR", $D17="AB", $D17="UR"),"",(IF(OR(G$10>0,L$10>0,Q$10>0,V$10>0),(AB$10*(IF(AND(G$10>0), IF(OR(G17="", G17="AB",G17="UR"),0,G17),0) +IF(AND(L$10>0), IF(OR(L17="",L17="AB",L17=""),0,L17),0)+IF(AND(Q$10>0), IF(OR(Q17="", Q17="AB",Q17="UR"),0,Q17),0)+IF(AND(V$10>0), IF(OR(V17="",V17="AB",V17="UR"),0,V17),0))/(G$10+L$10+Q$10+V$10))," "))) -> 43.75 | AC17: =IF(OR( $B17="", $B17="AB", $B17="UR", $C17="", $C17="AB", $C17="UR", $D17="AB", $D17="UR"),"",(IF(OR(H$10>0,M$10>0,R$10>0,W$10>0),(AC$10*(IF(AND(H$10>0), IF(OR(H17="", H17="AB",H17="UR"),0,H17),0) +IF(AND(M$10>0), IF(OR(M17="",M17="AB",M17=""),0,M17),0)+IF(AND(R$10>0), IF(OR(R17="", R17="AB",R17="UR"),0,R17),0)+IF(AND(W$10>0), IF(OR(W17="",W17="AB",W17="UR"),0,W17),0))/(H$10+M$10+R$10+W$10))," "))) -> 40 | AD17: =IF(OR( $B17="", $B17="AB", $B17="UR", $C17="", $C17="AB", $C17="UR", $D17="AB", $D17="UR"),"",(IF(OR(I$10>0,N$10>0,S$10>0,X$10>0),(AD$10*(IF(AND(I$10>0), IF(OR(I17="", I17="AB",I17="UR"),0,I17),0) +IF(AND(N$10>0), IF(OR(N17="",N17="AB",N17=""),0,N17),0)+IF(AND(S$10>0), IF(OR(S17="", S17="AB",S17="UR"),0,S17),0)+IF(AND(X$10>0), IF(OR(X17="",X17="AB",X17="UR"),0,X17),0))/(I$10+N$10+S$10+X$10))," "))) | AE17: =IF(C17="","",IFERROR(AVERAGE(Z17:AD17),"")) -> 55.659722
A18: 8 | B18: =IF('INTERACTION-PAGE'!B18="","",'INTERACTION-PAGE'!B18) -> MEB21012 | C18: =IF('INTERACTION-PAGE'!C18="","",'INTERACTION-PAGE'!C18) -> YUSUF ALI | D18: =IF('INTERACTION-PAGE'!D18="","",'INTERACTION-PAGE'!D18) | E18: =IF('INTERACTION-PAGE'!E18="","",'INTERACTION-PAGE'!E18) -> 5 | F18: =IF('INTERACTION-PAGE'!F18="","",'INTERACTION-PAGE'!F18) -> 8.5 | G18: =IF('INTERACTION-PAGE'!G18="","",'INTERACTION-PAGE'!G18) | H18: =IF('INTERACTION-PAGE'!H18="","",'INTERACTION-PAGE'!H18) | I18: =IF('INTERACTION-PAGE'!I18="","",'INTERACTION-PAGE'!I18) | ... X18: =IF('INTERACTION-PAGE'!X18="","",'INTERACTION-PAGE'!X18) | Y18: =IF(OR( $B18="", $B18="AB", $B18="UR", $C18="", $C18="AB", $C18="UR", $D18="AB", $D18="UR"),"",(IF(OR(I$8>0,N$8>0,S$8>0,X$8>0),(100*SUM(E18:X18)/(I$8+N$8+S$8+X$8))," "))) -> 48.333333 | Z18: =IF(OR( $B18="", $B18="AB", $B18="UR", $C18="", $C18="AB", $C18="UR", $D18="AB", $D18="UR"),"",(IF(OR(E$10>0,J$10>0,O$10>0,T$10>0),(Z$10*(IF(AND(E$10>0), IF(OR(E18="", E18="AB",E18="UR"),0,E18),0) +IF(AND(J$10>0), IF(OR(J18="",J18="AB",J18=""),0,J18),0)+IF(AND(O$10>0), IF(OR(O18="", O18="AB",O18="UR"),0,O18),0)+IF(AND(T$10>0), IF(OR(T18="",T18="AB",T18="UR"),0,T18),0))/(E$10+J$10+O$10+T$10))," "))) -> 63.888889 | AA18: =IF(OR( $B18="", $B18="AB", $B18="UR", $C18="", $C18="AB", $C18="UR", $D18="AB", $D18="UR"),"",(IF(OR(F$10>0,K$10>0,P$10>0,U$10>0),(AA$10*(IF(AND(F$10>0), IF(OR(F18="", F18="AB",F18="UR"),0,F18),0) +IF(AND(K$10>0), IF(OR(K18="",K18="AB",K18=""),0,K18),0)+IF(AND(P$10>0), IF(OR(P18="", P18="AB",P18="UR"),0,P18),0)+IF(AND(U$10>0), IF(OR(U18="",U18="AB",U18="UR"),0,U18),0))/(F$10+K$10+P$10+U$10))," "))) -> 55.128205 | AB18: =IF(OR( $B18="", $B18="AB", $B18="UR", $C18="", $C18="AB", $C18="UR", $D18="AB", $D18="UR"),"",(IF(OR(G$10>0,L$10>0,Q$10>0,V$10>0),(AB$10*(IF(AND(G$10>0), IF(OR(G18="", G18="AB",G18="UR"),0,G18),0) +IF(AND(L$10>0), IF(OR(L18="",L18="AB",L18=""),0,L18),0)+IF(AND(Q$10>0), IF(OR(Q18="", Q18="AB",Q18="UR"),0,Q18),0)+IF(AND(V$10>0), IF(OR(V18="",V18="AB",V18="UR"),0,V18),0))/(G$10+L$10+Q$10+V$10))," "))) -> 40 | AC18: =IF(OR( $B18="", $B18="AB", $B18="UR", $C18="", $C18="AB", $C18="UR", $D18="AB", $D18="UR"),"",(IF(OR(H$10>0,M$10>0,R$10>0,W$10>0),(AC$10*(IF(AND(H$10>0), IF(OR(H18="", H18="AB",H18="UR"),0,H18),0) +IF(AND(M$10>0), IF(OR(M18="",M18="AB",M18=""),0,M18),0)+IF(AND(R$10>0), IF(OR(R18="", R18="AB",R18="UR"),0,R18),0)+IF(AND(W$10>0), IF(OR(W18="",W18="AB",W18="UR"),0,W18),0))/(H$10+M$10+R$10+W$10))," "))) -> 34.285714 | AD18: =IF(OR( $B18="", $B18="AB", $B18="UR", $C18="", $C18="AB", $C18="UR", $D18="AB", $D18="UR"),"",(IF(OR(I$10>0,N$10>0,S$10>0,X$10>0),(AD$10*(IF(AND(I$10>0), IF(OR(I18="", I18="AB",I18="UR"),0,I18),0) +IF(AND(N$10>0), IF(OR(N18="",N18="AB",N18=""),0,N18),0)+IF(AND(S$10>0), IF(OR(S18="", S18="AB",S18="UR"),0,S18),0)+IF(AND(X$10>0), IF(OR(X18="",X18="AB",X18="UR"),0,X18),0))/(I$10+N$10+S$10+X$10))," "))) | AE18: =IF(C18="","",IFERROR(AVERAGE(Z18:AD18),"")) -> 48.325702
A19: 9 | B19: =IF('INTERACTION-PAGE'!B19="","",'INTERACTION-PAGE'!B19) -> MEB21013 | C19: =IF('INTERACTION-PAGE'!C19="","",'INTERACTION-PAGE'!C19) -> MUSKAN BORGOHAIN | D19: =IF('INTERACTION-PAGE'!D19="","",'INTERACTION-PAGE'!D19) | E19: =IF('INTERACTION-PAGE'!E19="","",'INTERACTION-PAGE'!E19) -> 6 | F19: =IF('INTERACTION-PAGE'!F19="","",'INTERACTION-PAGE'!F19) -> 8.5 | G19: =IF('INTERACTION-PAGE'!G19="","",'INTERACTION-PAGE'!G19) | H19: =IF('INTERACTION-PAGE'!H19="","",'INTERACTION-PAGE'!H19) | I19: =IF('INTERACTION-PAGE'!I19="","",'INTERACTION-PAGE'!I19) | ... X19: =IF('INTERACTION-PAGE'!X19="","",'INTERACTION-PAGE'!X19) | Y19: =IF(OR( $B19="", $B19="AB", $B19="UR", $C19="", $C19="AB", $C19="UR", $D19="AB", $D19="UR"),"",(IF(OR(I$8>0,N$8>0,S$8>0,X$8>0),(100*SUM(E19:X19)/(I$8+N$8+S$8+X$8))," "))) -> 57 | Z19: =IF(OR( $B19="", $B19="AB", $B19="UR", $C19="", $C19="AB", $C19="UR", $D19="AB", $D19="UR"),"",(IF(OR(E$10>0,J$10>0,O$10>0,T$10>0),(Z$10*(IF(AND(E$10>0), IF(OR(E19="", E19="AB",E19="UR"),0,E19),0) +IF(AND(J$10>0), IF(OR(J19="",J19="AB",J19=""),0,J19),0)+IF(AND(O$10>0), IF(OR(O19="", O19="AB",O19="UR"),0,O19),0)+IF(AND(T$10>0), IF(OR(T19="",T19="AB",T19="UR"),0,T19),0))/(E$10+J$10+O$10+T$10))," "))) -> 72.222222 | AA19: =IF(OR( $B19="", $B19="AB", $B19="UR", $C19="", $C19="AB", $C19="UR", $D19="AB", $D19="UR"),"",(IF(OR(F$10>0,K$10>0,P$10>0,U$10>0),(AA$10*(IF(AND(F$10>0), IF(OR(F19="", F19="AB",F19="UR"),0,F19),0) +IF(AND(K$10>0), IF(OR(K19="",K19="AB",K19=""),0,K19),0)+IF(AND(P$10>0), IF(OR(P19="", P19="AB",P19="UR"),0,P19),0)+IF(AND(U$10>0), IF(OR(U19="",U19="AB",U19="UR"),0,U19),0))/(F$10+K$10+P$10+U$10))," "))) -> 62.820513 | AB19: =IF(OR( $B19="", $B19="AB", $B19="UR", $C19="", $C19="AB", $C19="UR", $D19="AB", $D19="UR"),"",(IF(OR(G$10>0,L$10>0,Q$10>0,V$10>0),(AB$10*(IF(AND(G$10>0), IF(OR(G19="", G19="AB",G19="UR"),0,G19),0) +IF(AND(L$10>0), IF(OR(L19="",L19="AB",L19=""),0,L19),0)+IF(AND(Q$10>0), IF(OR(Q19="", Q19="AB",Q19="UR"),0,Q19),0)+IF(AND(V$10>0), IF(OR(V19="",V19="AB",V19="UR"),0,V19),0))/(G$10+L$10+Q$10+V$10))," "))) -> 48.75 | AC19: =IF(OR( $B19="", $B19="AB", $B19="UR", $C19="", $C19="AB", $C19="UR", $D19="AB", $D19="UR"),"",(IF(OR(H$10>0,M$10>0,R$10>0,W$10>0),(AC$10*(IF(AND(H$10>0), IF(OR(H19="", H19="AB",H19="UR"),0,H19),0) +IF(AND(M$10>0), IF(OR(M19="",M19="AB",M19=""),0,M19),0)+IF(AND(R$10>0), IF(OR(R19="", R19="AB",R19="UR"),0,R19),0)+IF(AND(W$10>0), IF(OR(W19="",W19="AB",W19="UR"),0,W19),0))/(H$10+M$10+R$10+W$10))," "))) -> 44.285714 | AD19: =IF(OR( $B19="", $B19="AB", $B19="UR", $C19="", $C19="AB", $C19="UR", $D19="AB", $D19="UR"),"",(IF(OR(I$10>0,N$10>0,S$10>0,X$10>0),(AD$10*(IF(AND(I$10>0), IF(OR(I19="", I19="AB",I19="UR"),0,I19),0) +IF(AND(N$10>0), IF(OR(N19="",N19="AB",N19=""),0,N19),0)+IF(AND(S$10>0), IF(OR(S19="", S19="AB",S19="UR"),0,S19),0)+IF(AND(X$10>0), IF(OR(X19="",X19="AB",X19="UR"),0,X19),0))/(I$10+N$10+S$10+X$10))," "))) | AE19: =IF(C19="","",IFERROR(AVERAGE(Z19:AD19),"")) -> 57.019612
A20: 10 | B20: =IF('INTERACTION-PAGE'!B20="","",'INTERACTION-PAGE'!B20) -> MEB21014 | C20: =IF('INTERACTION-PAGE'!C20="","",'INTERACTION-PAGE'!C20) -> SARFARAZ SAMIM HAQUE | D20: =IF('INTERACTION-PAGE'!D20="","",'INTERACTION-PAGE'!D20) | E20: =IF('INTERACTION-PAGE'!E20="","",'INTERACTION-PAGE'!E20) -> 8 | F20: =IF('INTERACTION-PAGE'!F20="","",'INTERACTION-PAGE'!F20) -> 13 | G20: =IF('INTERACTION-PAGE'!G20="","",'INTERACTION-PAGE'!G20) | H20: =IF('INTERACTION-PAGE'!H20="","",'INTERACTION-PAGE'!H20) | I20: =IF('INTERACTION-PAGE'!I20="","",'INTERACTION-PAGE'!I20) | ... X20: =IF('INTERACTION-PAGE'!X20="","",'INTERACTION-PAGE'!X20) | Y20: =IF(OR( $B20="", $B20="AB", $B20="UR", $C20="", $C20="AB", $C20="UR", $D20="AB", $D20="UR"),"",(IF(OR(I$8>0,N$8>0,S$8>0,X$8>0),(100*SUM(E20:X20)/(I$8+N$8+S$8+X$8))," "))) -> 64 | Z20: =IF(OR( $B20="", $B20="AB", $B20="UR", $C20="", $C20="AB", $C20="UR", $D20="AB", $D20="UR"),"",(IF(OR(E$10>0,J$10>0,O$10>0,T$10>0),(Z$10*(IF(AND(E$10>0), IF(OR(E20="", E20="AB",E20="UR"),0,E20),0) +IF(AND(J$10>0), IF(OR(J20="",J20="AB",J20=""),0,J20),0)+IF(AND(O$10>0), IF(OR(O20="", O20="AB",O20="UR"),0,O20),0)+IF(AND(T$10>0), IF(OR(T20="",T20="AB",T20="UR"),0,T20),0))/(E$10+J$10+O$10+T$10))," "))) -> 77.777778 | AA20: =IF(OR( $B20="", $B20="AB", $B20="UR", $C20="", $C20="AB", $C20="UR", $D20="AB", $D20="UR"),"",(IF(OR(F$10>0,K$10>0,P$10>0,U$10>0),(AA$10*(IF(AND(F$10>0), IF(OR(F20="", F20="AB",F20="UR"),0,F20),0) +IF(AND(K$10>0), IF(OR(K20="",K20="AB",K20=""),0,K20),0)+IF(AND(P$10>0), IF(OR(P20="", P20="AB",P20="UR"),0,P20),0)+IF(AND(U$10>0), IF(OR(U20="",U20="AB",U20="UR"),0,U20),0))/(F$10+K$10+P$10+U$10))," "))) -> 74.358974 | AB20: =IF(OR( $B20="", $B20="AB", $B20="UR", $C20="", $C20="AB", $C20="UR", $D20="AB", $D20="UR"),"",(IF(OR(G$10>0,L$10>0,Q$10>0,V$10>0),(AB$10*(IF(AND(G$10>0), IF(OR(G20="", G20="AB",G20="UR"),0,G20),0) +IF(AND(L$10>0), IF(OR(L20="",L20="AB",L20=""),0,L20),0)+IF(AND(Q$10>0), IF(OR(Q20="", Q20="AB",Q20="UR"),0,Q20),0)+IF(AND(V$10>0), IF(OR(V20="",V20="AB",V20="UR"),0,V20),0))/(G$10+L$10+Q$10+V$10))," "))) -> 52.5 | AC20: =IF(OR( $B20="", $B20="AB", $B20="UR", $C20="", $C20="AB", $C20="UR", $D20="AB", $D20="UR"),"",(IF(OR(H$10>0,M$10>0,R$10>0,W$10>0),(AC$10*(IF(AND(H$10>0), IF(OR(H20="", H20="AB",H20="UR"),0,H20),0) +IF(AND(M$10>0), IF(OR(M20="",M20="AB",M20=""),0,M20),0)+IF(AND(R$10>0), IF(OR(R20="", R20="AB",R20="UR"),0,R20),0)+IF(AND(W$10>0), IF(OR(W20="",W20="AB",W20="UR"),0,W20),0))/(H$10+M$10+R$10+W$10))," "))) -> 51.428571 | AD20: =IF(OR( $B20="", $B20="AB", $B20="UR", $C20="", $C20="AB", $C20="UR", $D20="AB", $D20="UR"),"",(IF(OR(I$10>0,N$10>0,S$10>0,X$10>0),(AD$10*(IF(AND(I$10>0), IF(OR(I20="", I20="AB",I20="UR"),0,I20),0) +IF(AND(N$10>0), IF(OR(N20="",N20="AB",N20=""),0,N20),0)+IF(AND(S$10>0), IF(OR(S20="", S20="AB",S20="UR"),0,S20),0)+IF(AND(X$10>0), IF(OR(X20="",X20="AB",X20="UR"),0,X20),0))/(I$10+N$10+S$10+X$10))," "))) | AE20: =IF(C20="","",IFERROR(AVERAGE(Z20:AD20),"")) -> 64.016331
A21: 11 | B21: =IF('INTERACTION-PAGE'!B21="","",'INTERACTION-PAGE'!B21) -> MEB21016 | C21: =IF('INTERACTION-PAGE'!C21="","",'INTERACTION-PAGE'!C21) -> ABHRAKIRAN DAS | D21: =IF('INTERACTION-PAGE'!D21="","",'INTERACTION-PAGE'!D21) | E21: =IF('INTERACTION-PAGE'!E21="","",'INTERACTION-PAGE'!E21) -> 7 | F21: =IF('INTERACTION-PAGE'!F21="","",'INTERACTION-PAGE'!F21) -> 11 | G21: =IF('INTERACTION-PAGE'!G21="","",'INTERACTION-PAGE'!G21) | H21: =IF('INTERACTION-PAGE'!H21="","",'INTERACTION-PAGE'!H21) | I21: =IF('INTERACTION-PAGE'!I21="","",'INTERACTION-PAGE'!I21) | ... X21: =IF('INTERACTION-PAGE'!X21="","",'INTERACTION-PAGE'!X21) | Y21: =IF(OR( $B21="", $B21="AB", $B21="UR", $C21="", $C21="AB", $C21="UR", $D21="AB", $D21="UR"),"",(IF(OR(I$8>0,N$8>0,S$8>0,X$8>0),(100*SUM(E21:X21)/(I$8+N$8+S$8+X$8))," "))) -> 39 | Z21: =IF(OR( $B21="", $B21="AB", $B21="UR", $C21="", $C21="AB", $C21="UR", $D21="AB", $D21="UR"),"",(IF(OR(E$10>0,J$10>0,O$10>0,T$10>0),(Z$10*(IF(AND(E$10>0), IF(OR(E21="", E21="AB",E21="UR"),0,E21),0) +IF(AND(J$10>0), IF(OR(J21="",J21="AB",J21=""),0,J21),0)+IF(AND(O$10>0), IF(OR(O21="", O21="AB",O21="UR"),0,O21),0)+IF(AND(T$10>0), IF(OR(T21="",T21="AB",T21="UR"),0,T21),0))/(E$10+J$10+O$10+T$10))," "))) -> 63.888889 | AA21: =IF(OR( $B21="", $B21="AB", $B21="UR", $C21="", $C21="AB", $C21="UR", $D21="AB", $D21="UR"),"",(IF(OR(F$10>0,K$10>0,P$10>0,U$10>0),(AA$10*(IF(AND(F$10>0), IF(OR(F21="", F21="AB",F21="UR"),0,F21),0) +IF(AND(K$10>0), IF(OR(K21="",K21="AB",K21=""),0,K21),0)+IF(AND(P$10>0), IF(OR(P21="", P21="AB",P21="UR"),0,P21),0)+IF(AND(U$10>0), IF(OR(U21="",U21="AB",U21="UR"),0,U21),0))/(F$10+K$10+P$10+U$10))," "))) -> 58.974359 | AB21: =IF(OR( $B21="", $B21="AB", $B21="UR", $C21="", $C21="AB", $C21="UR", $D21="AB", $D21="UR"),"",(IF(OR(G$10>0,L$10>0,Q$10>0,V$10>0),(AB$10*(IF(AND(G$10>0), IF(OR(G21="", G21="AB",G21="UR"),0,G21),0) +IF(AND(L$10>0), IF(OR(L21="",L21="AB",L21=""),0,L21),0)+IF(AND(Q$10>0), IF(OR(Q21="", Q21="AB",Q21="UR"),0,Q21),0)+IF(AND(V$10>0), IF(OR(V21="",V21="AB",V21="UR"),0,V21),0))/(G$10+L$10+Q$10+V$10))," "))) -> 18.75 | AC21: =IF(OR( $B21="", $B21="AB", $B21="UR", $C21="", $C21="AB", $C21="UR", $D21="AB", $D21="UR"),"",(IF(OR(H$10>0,M$10>0,R$10>0,W$10>0),(AC$10*(IF(AND(H$10>0), IF(OR(H21="", H21="AB",H21="UR"),0,H21),0) +IF(AND(M$10>0), IF(OR(M21="",M21="AB",M21=""),0,M21),0)+IF(AND(R$10>0), IF(OR(R21="", R21="AB",R21="UR"),0,R21),0)+IF(AND(W$10>0), IF(OR(W21="",W21="AB",W21="UR"),0,W21),0))/(H$10+M$10+R$10+W$10))," "))) -> 14.285714 | AD21: =IF(OR( $B21="", $B21="AB", $B21="UR", $C21="", $C21="AB", $C21="UR", $D21="AB", $D21="UR"),"",(IF(OR(I$10>0,N$10>0,S$10>0,X$10>0),(AD$10*(IF(AND(I$10>0), IF(OR(I21="", I21="AB",I21="UR"),0,I21),0) +IF(AND(N$10>0), IF(OR(N21="",N21="AB",N21=""),0,N21),0)+IF(AND(S$10>0), IF(OR(S21="", S21="AB",S21="UR"),0,S21),0)+IF(AND(X$10>0), IF(OR(X21="",X21="AB",X21="UR"),0,X21),0))/(I$10+N$10+S$10+X$10))," "))) | AE21: =IF(C21="","",IFERROR(AVERAGE(Z21:AD21),"")) -> 38.974741
A22: 12 | B22: =IF('INTERACTION-PAGE'!B22="","",'INTERACTION-PAGE'!B22) -> MEB21020 | C22: =IF('INTERACTION-PAGE'!C22="","",'INTERACTION-PAGE'!C22) -> ZAHEED AKHTAR | D22: =IF('INTERACTION-PAGE'!D22="","",'INTERACTION-PAGE'!D22) | E22: =IF('INTERACTION-PAGE'!E22="","",'INTERACTION-PAGE'!E22) -> 7 | F22: =IF('INTERACTION-PAGE'!F22="","",'INTERACTION-PAGE'!F22) -> 9.5 | G22: =IF('INTERACTION-PAGE'!G22="","",'INTERACTION-PAGE'!G22) | H22: =IF('INTERACTION-PAGE'!H22="","",'INTERACTION-PAGE'!H22) | I22: =IF('INTERACTION-PAGE'!I22="","",'INTERACTION-PAGE'!I22) | ... X22: =IF('INTERACTION-PAGE'!X22="","",'INTERACTION-PAGE'!X22) | Y22: =IF(OR( $B22="", $B22="AB", $B22="UR", $C22="", $C22="AB", $C22="UR", $D22="AB", $D22="UR"),"",(IF(OR(I$8>0,N$8>0,S$8>0,X$8>0),(100*SUM(E22:X22)/(I$8+N$8+S$8+X$8))," "))) -> 51.333333 | Z22: =IF(OR( $B22="", $B22="AB", $B22="UR", $C22="", $C22="AB", $C22="UR", $D22="AB", $D22="UR"),"",(IF(OR(E$10>0,J$10>0,O$10>0,T$10>0),(Z$10*(IF(AND(E$10>0), IF(OR(E22="", E22="AB",E22="UR"),0,E22),0) +IF(AND(J$10>0), IF(OR(J22="",J22="AB",J22=""),0,J22),0)+IF(AND(O$10>0), IF(OR(O22="", O22="AB",O22="UR"),0,O22),0)+IF(AND(T$10>0), IF(OR(T22="",T22="AB",T22="UR"),0,T22),0))/(E$10+J$10+O$10+T$10))," "))) -> 69.444444 | AA22: =IF(OR( $B22="", $B22="AB", $B22="UR", $C22="", $C22="AB", $C22="UR", $D22="AB", $D22="UR"),"",(IF(OR(F$10>0,K$10>0,P$10>0,U$10>0),(AA$10*(IF(AND(F$10>0), IF(OR(F22="", F22="AB",F22="UR"),0,F22),0) +IF(AND(K$10>0), IF(OR(K22="",K22="AB",K22=""),0,K22),0)+IF(AND(P$10>0), IF(OR(P22="", P22="AB",P22="UR"),0,P22),0)+IF(AND(U$10>0), IF(OR(U22="",U22="AB",U22="UR"),0,U22),0))/(F$10+K$10+P$10+U$10))," "))) -> 57.692308 | AB22: =IF(OR( $B22="", $B22="AB", $B22="UR", $C22="", $C22="AB", $C22="UR", $D22="AB", $D22="UR"),"",(IF(OR(G$10>0,L$10>0,Q$10>0,V$10>0),(AB$10*(IF(AND(G$10>0), IF(OR(G22="", G22="AB",G22="UR"),0,G22),0) +IF(AND(L$10>0), IF(OR(L22="",L22="AB",L22=""),0,L22),0)+IF(AND(Q$10>0), IF(OR(Q22="", Q22="AB",Q22="UR"),0,Q22),0)+IF(AND(V$10>0), IF(OR(V22="",V22="AB",V22="UR"),0,V22),0))/(G$10+L$10+Q$10+V$10))," "))) -> 42.5 | AC22: =IF(OR( $B22="", $B22="AB", $B22="UR", $C22="", $C22="AB", $C22="UR", $D22="AB", $D22="UR"),"",(IF(OR(H$10>0,M$10>0,R$10>0,W$10>0),(AC$10*(IF(AND(H$10>0), IF(OR(H22="", H22="AB",H22="UR"),0,H22),0) +IF(AND(M$10>0), IF(OR(M22="",M22="AB",M22=""),0,M22),0)+IF(AND(R$10>0), IF(OR(R22="", R22="AB",R22="UR"),0,R22),0)+IF(AND(W$10>0), IF(OR(W22="",W22="AB",W22="UR"),0,W22),0))/(H$10+M$10+R$10+W$10))," "))) -> 35.714286 | AD22: =IF(OR( $B22="", $B22="AB", $B22="UR", $C22="", $C22="AB", $C22="UR", $D22="AB", $D22="UR"),"",(IF(OR(I$10>0,N$10>0,S$10>0,X$10>0),(AD$10*(IF(AND(I$10>0), IF(OR(I22="", I22="AB",I22="UR"),0,I22),0) +IF(AND(N$10>0), IF(OR(N22="",N22="AB",N22=""),0,N22),0)+IF(AND(S$10>0), IF(OR(S22="", S22="AB",S22="UR"),0,S22),0)+IF(AND(X$10>0), IF(OR(X22="",X22="AB",X22="UR"),0,X22),0))/(I$10+N$10+S$10+X$10))," "))) | AE22: =IF(C22="","",IFERROR(AVERAGE(Z22:AD22),"")) -> 51.337759
A23: 13 | B23: =IF('INTERACTION-PAGE'!B23="","",'INTERACTION-PAGE'!B23) -> MEB21021 | C23: =IF('INTERACTION-PAGE'!C23="","",'INTERACTION-PAGE'!C23) -> DHYANABH SAIKIA | D23: =IF('INTERACTION-PAGE'!D23="","",'INTERACTION-PAGE'!D23) | E23: =IF('INTERACTION-PAGE'!E23="","",'INTERACTION-PAGE'!E23) -> 6 | F23: =IF('INTERACTION-PAGE'!F23="","",'INTERACTION-PAGE'!F23) -> 10 | G23: =IF('INTERACTION-PAGE'!G23="","",'INTERACTION-PAGE'!G23) | H23: =IF('INTERACTION-PAGE'!H23="","",'INTERACTION-PAGE'!H23) | I23: =IF('INTERACTION-PAGE'!I23="","",'INTERACTION-PAGE'!I23) | ... X23: =IF('INTERACTION-PAGE'!X23="","",'INTERACTION-PAGE'!X23) | Y23: =IF(OR( $B23="", $B23="AB", $B23="UR", $C23="", $C23="AB", $C23="UR", $D23="AB", $D23="UR"),"",(IF(OR(I$8>0,N$8>0,S$8>0,X$8>0),(100*SUM(E23:X23)/(I$8+N$8+S$8+X$8))," "))) -> 49 | Z23: =IF(OR( $B23="", $B23="AB", $B23="UR", $C23="", $C23="AB", $C23="UR", $D23="AB", $D23="UR"),"",(IF(OR(E$10>0,J$10>0,O$10>0,T$10>0),(Z$10*(IF(AND(E$10>0), IF(OR(E23="", E23="AB",E23="UR"),0,E23),0) +IF(AND(J$10>0), IF(OR(J23="",J23="AB",J23=""),0,J23),0)+IF(AND(O$10>0), IF(OR(O23="", O23="AB",O23="UR"),0,O23),0)+IF(AND(T$10>0), IF(OR(T23="",T23="AB",T23="UR"),0,T23),0))/(E$10+J$10+O$10+T$10))," "))) -> 61.111111 | AA23: =IF(OR( $B23="", $B23="AB", $B23="UR", $C23="", $C23="AB", $C23="UR", $D23="AB", $D23="UR"),"",(IF(OR(F$10>0,K$10>0,P$10>0,U$10>0),(AA$10*(IF(AND(F$10>0), IF(OR(F23="", F23="AB",F23="UR"),0,F23),0) +IF(AND(K$10>0), IF(OR(K23="",K23="AB",K23=""),0,K23),0)+IF(AND(P$10>0), IF(OR(P23="", P23="AB",P23="UR"),0,P23),0)+IF(AND(U$10>0), IF(OR(U23="",U23="AB",U23="UR"),0,U23),0))/(F$10+K$10+P$10+U$10))," "))) -> 58.974359 | AB23: =IF(OR( $B23="", $B23="AB", $B23="UR", $C23="", $C23="AB", $C23="UR", $D23="AB", $D23="UR"),"",(IF(OR(G$10>0,L$10>0,Q$10>0,V$10>0),(AB$10*(IF(AND(G$10>0), IF(OR(G23="", G23="AB",G23="UR"),0,G23),0) +IF(AND(L$10>0), IF(OR(L23="",L23="AB",L23=""),0,L23),0)+IF(AND(Q$10>0), IF(OR(Q23="", Q23="AB",Q23="UR"),0,Q23),0)+IF(AND(V$10>0), IF(OR(V23="",V23="AB",V23="UR"),0,V23),0))/(G$10+L$10+Q$10+V$10))," "))) -> 40 | AC23: =IF(OR( $B23="", $B23="AB", $B23="UR", $C23="", $C23="AB", $C23="UR", $D23="AB", $D23="UR"),"",(IF(OR(H$10>0,M$10>0,R$10>0,W$10>0),(AC$10*(IF(AND(H$10>0), IF(OR(H23="", H23="AB",H23="UR"),0,H23),0) +IF(AND(M$10>0), IF(OR(M23="",M23="AB",M23=""),0,M23),0)+IF(AND(R$10>0), IF(OR(R23="", R23="AB",R23="UR"),0,R23),0)+IF(AND(W$10>0), IF(OR(W23="",W23="AB",W23="UR"),0,W23),0))/(H$10+M$10+R$10+W$10))," "))) -> 35.714286 | AD23: =IF(OR( $B23="", $B23="AB", $B23="UR", $C23="", $C23="AB", $C23="UR", $D23="AB", $D23="UR"),"",(IF(OR(I$10>0,N$10>0,S$10>0,X$10>0),(AD$10*(IF(AND(I$10>0), IF(OR(I23="", I23="AB",I23="UR"),0,I23),0) +IF(AND(N$10>0), IF(OR(N23="",N23="AB",N23=""),0,N23),0)+IF(AND(S$10>0), IF(OR(S23="", S23="AB",S23="UR"),0,S23),0)+IF(AND(X$10>0), IF(OR(X23="",X23="AB",X23="UR"),0,X23),0))/(I$10+N$10+S$10+X$10))," "))) | AE23: =IF(C23="","",IFERROR(AVERAGE(Z23:AD23),"")) -> 48.949939
... A71: 61 | B71: =IF('INTERACTION-PAGE'!B71="","",'INTERACTION-PAGE'!B71) | C71: =IF('INTERACTION-PAGE'!C71="","",'INTERACTION-PAGE'!C71) | D71: =IF('INTERACTION-PAGE'!D71="","",'INTERACTION-PAGE'!D71) | E71: =IF('INTERACTION-PAGE'!E71="","",'INTERACTION-PAGE'!E71) | F71: =IF('INTERACTION-PAGE'!F71="","",'INTERACTION-PAGE'!F71) | G71: =IF('INTERACTION-PAGE'!G71="","",'INTERACTION-PAGE'!G71) | H71: =IF('INTERACTION-PAGE'!H71="","",'INTERACTION-PAGE'!H71) | I71: =IF('INTERACTION-PAGE'!I71="","",'INTERACTION-PAGE'!I71) | ... X71: =IF('INTERACTION-PAGE'!X71="","",'INTERACTION-PAGE'!X71) | Y71: =IF(OR( $B71="", $B71="AB", $B71="UR", $C71="", $C71="AB", $C71="UR", $D71="AB", $D71="UR"),"",(IF(OR(I$8>0,N$8>0,S$8>0,X$8>0),(100*SUM(E71:X71)/(I$8+N$8+S$8+X$8))," "))) | Z71: =IF(OR( $B71="", $B71="AB", $B71="UR", $C71="", $C71="AB", $C71="UR", $D71="AB", $D71="UR"),"",(IF(OR(E$10>0,J$10>0,O$10>0,T$10>0),(Z$10*(IF(AND(E$10>0), IF(OR(E71="", E71="AB",E71="UR"),0,E71),0) +IF(AND(J$10>0), IF(OR(J71="",J71="AB",J71=""),0,J71),0)+IF(AND(O$10>0), IF(OR(O71="", O71="AB",O71="UR"),0,O71),0)+IF(AND(T$10>0), IF(OR(T71="",T71="AB",T71="UR"),0,T71),0))/(E$10+J$10+O$10+T$10))," "))) | AA71: =IF(OR( $B71="", $B71="AB", $B71="UR", $C71="", $C71="AB", $C71="UR", $D71="AB", $D71="UR"),"",(IF(OR(F$10>0,K$10>0,P$10>0,U$10>0),(AA$10*(IF(AND(F$10>0), IF(OR(F71="", F71="AB",F71="UR"),0,F71),0) +IF(AND(K$10>0), IF(OR(K71="",K71="AB",K71=""),0,K71),0)+IF(AND(P$10>0), IF(OR(P71="", P71="AB",P71="UR"),0,P71),0)+IF(AND(U$10>0), IF(OR(U71="",U71="AB",U71="UR"),0,U71),0))/(F$10+K$10+P$10+U$10))," "))) | AB71: =IF(OR( $B71="", $B71="AB", $B71="UR", $C71="", $C71="AB", $C71="UR", $D71="AB", $D71="UR"),"",(IF(OR(G$10>0,L$10>0,Q$10>0,V$10>0),(AB$10*(IF(AND(G$10>0), IF(OR(G71="", G71="AB",G71="UR"),0,G71),0) +IF(AND(L$10>0), IF(OR(L71="",L71="AB",L71=""),0,L71),0)+IF(AND(Q$10>0), IF(OR(Q71="", Q71="AB",Q71="UR"),0,Q71),0)+IF(AND(V$10>0), IF(OR(V71="",V71="AB",V71="UR"),0,V71),0))/(G$10+L$10+Q$10+V$10))," "))) | AC71: =IF(OR( $B71="", $B71="AB", $B71="UR", $C71="", $C71="AB", $C71="UR", $D71="AB", $D71="UR"),"",(IF(OR(H$10>0,M$10>0,R$10>0,W$10>0),(AC$10*(IF(AND(H$10>0), IF(OR(H71="", H71="AB",H71="UR"),0,H71),0) +IF(AND(M$10>0), IF(OR(M71="",M71="AB",M71=""),0,M71),0)+IF(AND(R$10>0), IF(OR(R71="", R71="AB",R71="UR"),0,R71),0)+IF(AND(W$10>0), IF(OR(W71="",W71="AB",W71="UR"),0,W71),0))/(H$10+M$10+R$10+W$10))," "))) | AD71: =IF(OR( $B71="", $B71="AB", $B71="UR", $C71="", $C71="AB", $C71="UR", $D71="AB", $D71="UR"),"",(IF(OR(I$10>0,N$10>0,S$10>0,X$10>0),(AD$10*(IF(AND(I$10>0), IF(OR(I71="", I71="AB",I71="UR"),0,I71),0) +IF(AND(N$10>0), IF(OR(N71="",N71="AB",N71=""),0,N71),0)+IF(AND(S$10>0), IF(OR(S71="", S71="AB",S71="UR"),0,S71),0)+IF(AND(X$10>0), IF(OR(X71="",X71="AB",X71="UR"),0,X71),0))/(I$10+N$10+S$10+X$10))," "))) | AE71: =IF(C71="","",IFERROR(AVERAGE(Z71:AD71),""))
A72: 62 | B72: =IF('INTERACTION-PAGE'!#REF!="","",'INTERACTION-PAGE'!#REF!) -> #ERROR! | C72: =IF('INTERACTION-PAGE'!#REF!="","",'INTERACTION-PAGE'!#REF!) -> #ERROR! | D72: =IF('INTERACTION-PAGE'!#REF!="","",'INTERACTION-PAGE'!#REF!) -> #ERROR! | E72: =IF('INTERACTION-PAGE'!#REF!="","",'INTERACTION-PAGE'!#REF!) -> #ERROR! | F72: =IF('INTERACTION-PAGE'!#REF!="","",'INTERACTION-PAGE'!#REF!) -> #ERROR! | G72: =IF('INTERACTION-PAGE'!#REF!="","",'INTERACTION-PAGE'!#REF!) -> #ERROR! | H72: =IF('INTERACTION-PAGE'!#REF!="","",'INTERACTION-PAGE'!#REF!) -> #ERROR! | I72: =IF('INTERACTION-PAGE'!#REF!="","",'INTERACTION-PAGE'!#REF!) -> #ERROR! | ... X72: =IF('INTERACTION-PAGE'!#REF!="","",'INTERACTION-PAGE'!#REF!) -> #ERROR! | Y72: =IF(OR( $B72="", $B72="AB", $B72="UR", $C72="", $C72="AB", $C72="UR", $D72="AB", $D72="UR"),"",(IF(OR(I$8>0,N$8>0,S$8>0,X$8>0),(100*SUM(E72:X72)/(I$8+N$8+S$8+X$8))," "))) -> #ERROR! | Z72: =IF(OR( $B72="", $B72="AB", $B72="UR", $C72="", $C72="AB", $C72="UR", $D72="AB", $D72="UR"),"",(IF(OR(E$10>0,J$10>0,O$10>0,T$10>0),(Z$10*(IF(AND(E$10>0), IF(OR(E72="", E72="AB",E72="UR"),0,E72),0) +IF(AND(J$10>0), IF(OR(J72="",J72="AB",J72=""),0,J72),0)+IF(AND(O$10>0), IF(OR(O72="", O72="AB",O72="UR"),0,O72),0)+IF(AND(T$10>0), IF(OR(T72="",T72="AB",T72="UR"),0,T72),0))/(E$10+J$10+O$10+T$10))," "))) -> #ERROR! | AA72: =IF(OR( $B72="", $B72="AB", $B72="UR", $C72="", $C72="AB", $C72="UR", $D72="AB", $D72="UR"),"",(IF(OR(F$10>0,K$10>0,P$10>0,U$10>0),(AA$10*(IF(AND(F$10>0), IF(OR(F72="", F72="AB",F72="UR"),0,F72),0) +IF(AND(K$10>0), IF(OR(K72="",K72="AB",K72=""),0,K72),0)+IF(AND(P$10>0), IF(OR(P72="", P72="AB",P72="UR"),0,P72),0)+IF(AND(U$10>0), IF(OR(U72="",U72="AB",U72="UR"),0,U72),0))/(F$10+K$10+P$10+U$10))," "))) -> #ERROR! | AB72: =IF(OR( $B72="", $B72="AB", $B72="UR", $C72="", $C72="AB", $C72="UR", $D72="AB", $D72="UR"),"",(IF(OR(G$10>0,L$10>0,Q$10>0,V$10>0),(AB$10*(IF(AND(G$10>0), IF(OR(G72="", G72="AB",G72="UR"),0,G72),0) +IF(AND(L$10>0), IF(OR(L72="",L72="AB",L72=""),0,L72),0)+IF(AND(Q$10>0), IF(OR(Q72="", Q72="AB",Q72="UR"),0,Q72),0)+IF(AND(V$10>0), IF(OR(V72="",V72="AB",V72="UR"),0,V72),0))/(G$10+L$10+Q$10+V$10))," "))) -> #ERROR! | AC72: =IF(OR( $B72="", $B72="AB", $B72="UR", $C72="", $C72="AB", $C72="UR", $D72="AB", $D72="UR"),"",(IF(OR(H$10>0,M$10>0,R$10>0,W$10>0),(AC$10*(IF(AND(H$10>0), IF(OR(H72="", H72="AB",H72="UR"),0,H72),0) +IF(AND(M$10>0), IF(OR(M72="",M72="AB",M72=""),0,M72),0)+IF(AND(R$10>0), IF(OR(R72="", R72="AB",R72="UR"),0,R72),0)+IF(AND(W$10>0), IF(OR(W72="",W72="AB",W72="UR"),0,W72),0))/(H$10+M$10+R$10+W$10))," "))) -> #ERROR! | AD72: =IF(OR( $B72="", $B72="AB", $B72="UR", $C72="", $C72="AB", $C72="UR", $D72="AB", $D72="UR"),"",(IF(OR(I$10>0,N$10>0,S$10>0,X$10>0),(AD$10*(IF(AND(I$10>0), IF(OR(I72="", I72="AB",I72="UR"),0,I72),0) +IF(AND(N$10>0), IF(OR(N72="",N72="AB",N72=""),0,N72),0)+IF(AND(S$10>0), IF(OR(S72="", S72="AB",S72="UR"),0,S72),0)+IF(AND(X$10>0), IF(OR(X72="",X72="AB",X72="UR"),0,X72),0))/(I$10+N$10+S$10+X$10))," "))) -> #ERROR! | AE72: =IF(C72="","",IFERROR(AVERAGE(Z72:AD72),"")) -> #ERROR!
A73: 63 | B73: =IF('INTERACTION-PAGE'!#REF!="","",'INTERACTION-PAGE'!#REF!) -> #ERROR! | C73: =IF('INTERACTION-PAGE'!#REF!="","",'INTERACTION-PAGE'!#REF!) -> #ERROR! | D73: =IF('INTERACTION-PAGE'!#REF!="","",'INTERACTION-PAGE'!#REF!) -> #ERROR! | E73: =IF('INTERACTION-PAGE'!#REF!="","",'INTERACTION-PAGE'!#REF!) -> #ERROR! | F73: =IF('INTERACTION-PAGE'!#REF!="","",'INTERACTION-PAGE'!#REF!) -> #ERROR! | G73: =IF('INTERACTION-PAGE'!#REF!="","",'INTERACTION-PAGE'!#REF!) -> #ERROR! | H73: =IF('INTERACTION-PAGE'!#REF!="","",'INTERACTION-PAGE'!#REF!) -> #ERROR! | I73: =IF('INTERACTION-PAGE'!#REF!="","",'INTERACTION-PAGE'!#REF!) -> #ERROR! | ... X73: =IF('INTERACTION-PAGE'!#REF!="","",'INTERACTION-PAGE'!#REF!) -> #ERROR! | Y73: =IF(OR( $B73="", $B73="AB", $B73="UR", $C73="", $C73="AB", $C73="UR", $D73="AB", $D73="UR"),"",(IF(OR(I$8>0,N$8>0,S$8>0,X$8>0),(100*SUM(E73:X73)/(I$8+N$8+S$8+X$8))," "))) -> #ERROR! | Z73: =IF(OR( $B73="", $B73="AB", $B73="UR", $C73="", $C73="AB", $C73="UR", $D73="AB", $D73="UR"),"",(IF(OR(E$10>0,J$10>0,O$10>0,T$10>0),(Z$10*(IF(AND(E$10>0), IF(OR(E73="", E73="AB",E73="UR"),0,E73),0) +IF(AND(J$10>0), IF(OR(J73="",J73="AB",J73=""),0,J73),0)+IF(AND(O$10>0), IF(OR(O73="", O73="AB",O73="UR"),0,O73),0)+IF(AND(T$10>0), IF(OR(T73="",T73="AB",T73="UR"),0,T73),0))/(E$10+J$10+O$10+T$10))," "))) -> #ERROR! | AA73: =IF(OR( $B73="", $B73="AB", $B73="UR", $C73="", $C73="AB", $C73="UR", $D73="AB", $D73="UR"),"",(IF(OR(F$10>0,K$10>0,P$10>0,U$10>0),(AA$10*(IF(AND(F$10>0), IF(OR(F73="", F73="AB",F73="UR"),0,F73),0) +IF(AND(K$10>0), IF(OR(K73="",K73="AB",K73=""),0,K73),0)+IF(AND(P$10>0), IF(OR(P73="", P73="AB",P73="UR"),0,P73),0)+IF(AND(U$10>0), IF(OR(U73="",U73="AB",U73="UR"),0,U73),0))/(F$10+K$10+P$10+U$10))," "))) -> #ERROR! | AB73: =IF(OR( $B73="", $B73="AB", $B73="UR", $C73="", $C73="AB", $C73="UR", $D73="AB", $D73="UR"),"",(IF(OR(G$10>0,L$10>0,Q$10>0,V$10>0),(AB$10*(IF(AND(G$10>0), IF(OR(G73="", G73="AB",G73="UR"),0,G73),0) +IF(AND(L$10>0), IF(OR(L73="",L73="AB",L73=""),0,L73),0)+IF(AND(Q$10>0), IF(OR(Q73="", Q73="AB",Q73="UR"),0,Q73),0)+IF(AND(V$10>0), IF(OR(V73="",V73="AB",V73="UR"),0,V73),0))/(G$10+L$10+Q$10+V$10))," "))) -> #ERROR! | AC73: =IF(OR( $B73="", $B73="AB", $B73="UR", $C73="", $C73="AB", $C73="UR", $D73="AB", $D73="UR"),"",(IF(OR(H$10>0,M$10>0,R$10>0,W$10>0),(AC$10*(IF(AND(H$10>0), IF(OR(H73="", H73="AB",H73="UR"),0,H73),0) +IF(AND(M$10>0), IF(OR(M73="",M73="AB",M73=""),0,M73),0)+IF(AND(R$10>0), IF(OR(R73="", R73="AB",R73="UR"),0,R73),0)+IF(AND(W$10>0), IF(OR(W73="",W73="AB",W73="UR"),0,W73),0))/(H$10+M$10+R$10+W$10))," "))) -> #ERROR! | AD73: =IF(OR( $B73="", $B73="AB", $B73="UR", $C73="", $C73="AB", $C73="UR", $D73="AB", $D73="UR"),"",(IF(OR(I$10>0,N$10>0,S$10>0,X$10>0),(AD$10*(IF(AND(I$10>0), IF(OR(I73="", I73="AB",I73="UR"),0,I73),0) +IF(AND(N$10>0), IF(OR(N73="",N73="AB",N73=""),0,N73),0)+IF(AND(S$10>0), IF(OR(S73="", S73="AB",S73="UR"),0,S73),0)+IF(AND(X$10>0), IF(OR(X73="",X73="AB",X73="UR"),0,X73),0))/(I$10+N$10+S$10+X$10))," "))) -> #ERROR! | AE73: =IF(C73="","",IFERROR(AVERAGE(Z73:AD73),"")) -> #ERROR!
